{"errorMessage": "(psycopg2.OperationalError) connection to server at \"zaabt5szpidxovz3typgum2iam.dsql.us-east-2.on.aws\" (18.97.139.130), port 5432 failed: FATAL:  unable to accept connection, access denied\nDETAIL:  Session Id: w5tbph34oiono5yxqyd72zofnm\n\n(Background on this error at: https://sqlalche.me/e/20/e3q8)", "errorType": "OperationalError", "requestId": "a5c48f9b-6e7b-40b1-b89d-6d62d280b613", "stackTrace": ["  File \"/var/task/migrate.py\", line 8, in handler\n    run_migration()\n", "  File \"/var/task/migrate.py\", line 18, in run_migration\n    command.upgrade(alembic_cfg, \"head\")\n", "  File \"/var/task/alembic/command.py\", line 406, in upgrade\n    script.run_env()\n", "  File \"/var/task/alembic/script/base.py\", line 586, in run_env\n    util.load_python_file(self.dir, \"env.py\")\n", "  File \"/var/task/alembic/util/pyfiles.py\", line 95, in load_python_file\n    module = load_module_py(module_id, path)\n", "  File \"/var/task/alembic/util/pyfiles.py\", line 113, in load_module_py\n    spec.loader.exec_module(module)  # type: ignore\n", "  File \"<frozen importlib._bootstrap_external>\", line 999, in exec_module\n", "  File \"<frozen importlib._bootstrap>\", line 488, in _call_with_frames_removed\n", "  File \"/var/task/migrations/env.py\", line 138, in <module>\n    run_migrations_online()\n", "  File \"/var/task/migrations/env.py\", line 126, in run_migrations_online\n    with connectable.connect() as connection:\n", "  File \"/var/task/sqlalchemy/engine/base.py\", line 3274, in connect\n    return self._connection_cls(self)\n", "  File \"/var/task/sqlalchemy/engine/base.py\", line 148, in __init__\n    Connection._handle_dbapi_exception_noconnection(\n", "  File \"/var/task/sqlalchemy/engine/base.py\", line 2439, in _handle_dbapi_exception_noconnection\n    raise sqlalchemy_exception.with_traceback(exc_info[2]) from e\n", "  File \"/var/task/sqlalchemy/engine/base.py\", line 146, in __init__\n    self._dbapi_connection = engine.raw_connection()\n", "  File \"/var/task/sqlalchemy/engine/base.py\", line 3298, in raw_connection\n    return self.pool.connect()\n", "  File \"/var/task/sqlalchemy/pool/base.py\", line 449, in connect\n    return _ConnectionFairy._checkout(self)\n", "  File \"/var/task/sqlalchemy/pool/base.py\", line 1263, in _checkout\n    fairy = _ConnectionRecord.checkout(pool)\n", "  File \"/var/task/sqlalchemy/pool/base.py\", line 712, in checkout\n    rec = pool._do_get()\n", "  File \"/var/task/sqlalchemy/pool/impl.py\", line 308, in _do_get\n    return self._create_connection()\n", "  File \"/var/task/sqlalchemy/pool/base.py\", line 390, in _create_connection\n    return _ConnectionRecord(self)\n", "  File \"/var/task/sqlalchemy/pool/base.py\", line 674, in __init__\n    self.__connect()\n", "  File \"/var/task/sqlalchemy/pool/base.py\", line 900, in __connect\n    with util.safe_reraise():\n", "  File \"/var/task/sqlalchemy/util/langhelpers.py\", line 146, in __exit__\n    raise exc_value.with_traceback(exc_tb)\n", "  File \"/var/task/sqlalchemy/pool/base.py\", line 896, in __connect\n    self.dbapi_connection = connection = pool._invoke_creator(self)\n", "  File \"/var/task/sqlalchemy/engine/create.py\", line 646, in connect\n    return dialect.connect(*cargs, **cparams)\n", "  File \"/var/task/sqlalchemy/engine/default.py\", line 622, in connect\n    return self.loaded_dbapi.connect(*cargs, **cparams)\n", "  File \"/var/task/psycopg2/__init__.py\", line 122, in connect\n    conn = _connect(dsn, connection_factory=connection_factory, **kwasync)\n"]}